<?xml version="1.0" ?>

<robot name="Robot_Arm">

    <!-- Include materials-->
    <material name="Black">
        <color rgba="0.0 0.0 0.0 1.0" />
    </material>
    <material name="Gray">
        <color rgba="0.4 0.4 0.4 1.0" />
    </material>
    <material name="Red">
        <color rgba="0.8 0.0 0.0 1.0" />
    </material>
    <material name="White">
        <color rgba="1.0 1.0 1.0 1.0" />
    </material>
    <material name="Blue">
        <color rgba="0.0 0.0 1.0 1.0" />
    </material>
    <material name="Green">
        <color rgba="0.0 1.0 0.0 1.0" />
    </material>
    
    <!-- ////////////////////////////////////////////////////-->
    <!--transmission block-->
    <!-- ////////////////////////////////////////////////////////////-->
    <!-- chassis-->
    <link name="dummy" />
    <link name="chassis">
        <visual>
            <origin rpy="-1.57 0 1.57" xyz="0 0 0" />
            <geometry>
                <mesh filename="package://robot_arm/meshes/base assembly.dae" />
            </geometry>
        </visual>
        <collision>
            <origin rpy="-1.57 0 0" xyz="0 0 0" />
            <geometry>
                <mesh filename="package://robot_arm/meshes/base assembly.dae" />
            </geometry>
        </collision>
        <inertial>
            <mass value="5.0" />
            <inertia ixx="1.0" ixy="0.0" ixz="0.0" iyy="1.0" iyz="0.0" izz="1.0" />
            <origin xyz="0 0 0" rpy="0 0 0" />
        </inertial>
    </link>
    <joint name="dummy_joint" type="fixed">
        <origin rpy="0 0 0" xyz="0 0 0" />
        <parent link="dummy" />
        <child link="chassis" />
    </joint>
    <gazebo reference="chassis">
        <turnGravityOff>false</turnGravityOff>
        <plugin name="gazebo_ros_control" filename="libgazebo_ros_control.so">
            <robotNamespace>/</robotNamespace>
        </plugin>
    </gazebo>
    <!-- ///////////////////      Wheels      ///////////////////////   -->
    <link name="right_front_wheel">
        <visual>
            <origin rpy="1.57 0 0" xyz="0 0 0" />
            <geometry>
                <cylinder length="0.022" radius="0.011" />
            </geometry>
            <material name="Black" />
        </visual>
        <collision>
            <origin rpy="1.57 0 0" xyz="0 0 0" />
            <geometry>
                <cylinder length="0.022" radius="0.011" />
            </geometry>
        </collision>
        <inertial>
            <mass value="0.2" />
            <inertia ixx="2.4872222222222223e-05" ixy="0.0" ixz="0.0" iyy="2.4872222222222223e-05" iyz="0.0" izz="3.3611111111111116e-05" />
            <origin xyz="0 0 0" rpy="0 0 0" />
        </inertial>
    </link>
    <link name="right_front_wheel1">
        <visual>
            <origin rpy="0  1.57 0" xyz="0 0 0" />
            <geometry>
                <mesh filename="package://robot_arm/meshes/tyre11.dae" />
            </geometry>
            <material name="Black" />
        </visual>
        <collision>
            <origin rpy="0 1.57 0" xyz="0 0 0" />
            <geometry>
                <mesh filename="package://robot_arm/meshes/tyre11.dae" />
            </geometry>
        </collision>
        <inertial>
            <mass value="0.2" />
            <inertia ixx="0.00015931666666666667" ixy="0.0" ixz="0.0" iyy="0.00015931666666666667" iyz="0.0" izz="0.00030250000000000003" />
            <origin xyz="0 0 0" rpy="0 0 0" />
        </inertial>
    </link>
    <gazebo reference="right_front_wheel1">
        <material>Gazebo/Black</material>
        <turnGravityOff>false</turnGravityOff>
    </gazebo>
    <joint name="right_front_wheel_joint1" type="fixed">
        <parent link="right_front_wheel" />
        <child link="right_front_wheel1" />
        <origin rpy="0 0 0" xyz="0 0 0" />
    </joint>
    <gazebo reference="right_front_wheel">
        <mu1 value="200.0" />
        <mu2 value="100.0" />
        <kp value="10000000.0" />
        <kd value="1.0" />
        <material>Gazebo/Black</material>
    </gazebo>
    <joint name="right_front_wheel_joint" type="continuous">
        <parent link="chassis" />
        <child link="right_front_wheel" />
        <origin rpy="0 0 0" xyz="0.062 -0.115  0.015" />
        <axis xyz="0 1 0" />
        <limit effort="100" velocity="100" />
        <dynamics damping="0.0" friction="0.0" />
    </joint>
    <transmission name="right_front_wheel_trans">
        <type>transmission_interface/SimpleTransmission</type>
        <actuator name="right_front_wheel_motor">
            <hardwareInterface>hardware_interface/EffortJointInterface</hardwareInterface>
            <mechanicalReduction>1</mechanicalReduction>
        </actuator>
        <joint name="right_front_wheel_joint">
            <hardwareInterface>hardware_interface/VelocityJointInterface</hardwareInterface>
        </joint>
    </transmission>
    <link name="right_back_wheel">
        <visual>
            <origin rpy="1.57 0 0" xyz="0 0 0" />
            <geometry>
                <cylinder length="0.022" radius="0.011" />
            </geometry>
            <material name="Black" />
        </visual>
        <collision>
            <origin rpy="1.57 0 0" xyz="0 0 0" />
            <geometry>
                <cylinder length="0.022" radius="0.011" />
            </geometry>
        </collision>
        <inertial>
            <mass value="0.2" />
            <inertia ixx="2.4872222222222223e-05" ixy="0.0" ixz="0.0" iyy="2.4872222222222223e-05" iyz="0.0" izz="3.3611111111111116e-05" />
            <origin xyz="0 0 0" rpy="0 0 0" />
        </inertial>
    </link>
    <link name="right_back_wheel1">
        <visual>
            <origin rpy="0  1.57 0" xyz="0 0 0" />
            <geometry>
                <mesh filename="package://robot_arm/meshes/tyre11.dae" />
            </geometry>
            <material name="Black" />
        </visual>
        <collision>
            <origin rpy="0 1.57 0" xyz="0 0 0" />
            <geometry>
                <mesh filename="package://robot_arm/meshes/tyre11.dae" />
            </geometry>
        </collision>
        <inertial>
            <mass value="0.2" />
            <inertia ixx="0.00015931666666666667" ixy="0.0" ixz="0.0" iyy="0.00015931666666666667" iyz="0.0" izz="0.00030250000000000003" />
            <origin xyz="0 0 0" rpy="0 0 0" />
        </inertial>
    </link>
    <gazebo reference="right_back_wheel1">
        <material>Gazebo/Black</material>
        <turnGravityOff>false</turnGravityOff>
    </gazebo>
    <joint name="right_back_wheel_joint1" type="fixed">
        <parent link="right_back_wheel" />
        <child link="right_back_wheel1" />
        <origin rpy="0 0 0" xyz="0 0 0" />
    </joint>
    <gazebo reference="right_back_wheel">
        <mu1 value="200.0" />
        <mu2 value="100.0" />
        <kp value="10000000.0" />
        <kd value="1.0" />
        <material>Gazebo/Black</material>
    </gazebo>
    <joint name="right_back_wheel_joint" type="continuous">
        <parent link="chassis" />
        <child link="right_back_wheel" />
        <origin rpy="0 0 0" xyz="-0.058 -0.115  0.015" />
        <axis xyz="0 1 0" />
        <limit effort="100" velocity="100" />
        <dynamics damping="0.0" friction="0.0" />
    </joint>
    <transmission name="right_back_wheel_trans">
        <type>transmission_interface/SimpleTransmission</type>
        <actuator name="right_back_wheel_motor">
            <hardwareInterface>hardware_interface/EffortJointInterface</hardwareInterface>
            <mechanicalReduction>1</mechanicalReduction>
        </actuator>
        <joint name="right_back_wheel_joint">
            <hardwareInterface>hardware_interface/VelocityJointInterface</hardwareInterface>
        </joint>
    </transmission>
    <link name="left_front_wheel">
        <visual>
            <origin rpy="1.57 0 0" xyz="0 0 0" />
            <geometry>
                <cylinder length="0.022" radius="0.011" />
            </geometry>
            <material name="Black" />
        </visual>
        <collision>
            <origin rpy="1.57 0 0" xyz="0 0 0" />
            <geometry>
                <cylinder length="0.022" radius="0.011" />
            </geometry>
        </collision>
        <inertial>
            <mass value="0.2" />
            <inertia ixx="2.4872222222222223e-05" ixy="0.0" ixz="0.0" iyy="2.4872222222222223e-05" iyz="0.0" izz="3.3611111111111116e-05" />
            <origin xyz="0 0 0" rpy="0 0 0" />
        </inertial>
    </link>
    <link name="left_front_wheel1">
        <visual>
            <origin rpy="0  1.57 0" xyz="0 0 0" />
            <geometry>
                <mesh filename="package://robot_arm/meshes/tyre11.dae" />
            </geometry>
            <material name="Black" />
        </visual>
        <collision>
            <origin rpy="0 1.57 0" xyz="0 0 0" />
            <geometry>
                <mesh filename="package://robot_arm/meshes/tyre11.dae" />
            </geometry>
        </collision>
        <inertial>
            <mass value="0.2" />
            <inertia ixx="0.00015931666666666667" ixy="0.0" ixz="0.0" iyy="0.00015931666666666667" iyz="0.0" izz="0.00030250000000000003" />
            <origin xyz="0 0 0" rpy="0 0 0" />
        </inertial>
    </link>
    <gazebo reference="left_front_wheel1">
        <material>Gazebo/Black</material>
        <turnGravityOff>false</turnGravityOff>
    </gazebo>
    <joint name="left_front_wheel_joint1" type="fixed">
        <parent link="left_front_wheel" />
        <child link="left_front_wheel1" />
        <origin rpy="0 0 0" xyz="0 0 0" />
    </joint>
    <gazebo reference="left_front_wheel">
        <mu1 value="200.0" />
        <mu2 value="100.0" />
        <kp value="10000000.0" />
        <kd value="1.0" />
        <material>Gazebo/Black</material>
    </gazebo>
    <joint name="left_front_wheel_joint" type="continuous">
        <parent link="chassis" />
        <child link="left_front_wheel" />
        <origin rpy="0 0 0" xyz="0.062 0.115  0.015" />
        <axis xyz="0 1 0" />
        <limit effort="100" velocity="100" />
        <dynamics damping="0.0" friction="0.0" />
    </joint>
    <transmission name="left_front_wheel_trans">
        <type>transmission_interface/SimpleTransmission</type>
        <actuator name="left_front_wheel_motor">
            <hardwareInterface>hardware_interface/EffortJointInterface</hardwareInterface>
            <mechanicalReduction>1</mechanicalReduction>
        </actuator>
        <joint name="left_front_wheel_joint">
            <hardwareInterface>hardware_interface/VelocityJointInterface</hardwareInterface>
        </joint>
    </transmission>
    <link name="left_back_wheel">
        <visual>
            <origin rpy="1.57 0 0" xyz="0 0 0" />
            <geometry>
                <cylinder length="0.022" radius="0.011" />
            </geometry>
            <material name="Black" />
        </visual>
        <collision>
            <origin rpy="1.57 0 0" xyz="0 0 0" />
            <geometry>
                <cylinder length="0.022" radius="0.011" />
            </geometry>
        </collision>
        <inertial>
            <mass value="0.2" />
            <inertia ixx="2.4872222222222223e-05" ixy="0.0" ixz="0.0" iyy="2.4872222222222223e-05" iyz="0.0" izz="3.3611111111111116e-05" />
            <origin xyz="0 0 0" rpy="0 0 0" />
        </inertial>
    </link>
    <link name="left_back_wheel1">
        <visual>
            <origin rpy="0  1.57 0" xyz="0 0 0" />
            <geometry>
                <mesh filename="package://robot_arm/meshes/tyre11.dae" />
            </geometry>
            <material name="Black" />
        </visual>
        <collision>
            <origin rpy="0 1.57 0" xyz="0 0 0" />
            <geometry>
                <mesh filename="package://robot_arm/meshes/tyre11.dae" />
            </geometry>
        </collision>
        <inertial>
            <mass value="0.2" />
            <inertia ixx="0.00015931666666666667" ixy="0.0" ixz="0.0" iyy="0.00015931666666666667" iyz="0.0" izz="0.00030250000000000003" />
            <origin xyz="0 0 0" rpy="0 0 0" />
        </inertial>
    </link>
    <gazebo reference="left_back_wheel1">
        <material>Gazebo/Black</material>
        <turnGravityOff>false</turnGravityOff>
    </gazebo>
    <joint name="left_back_wheel_joint1" type="fixed">
        <parent link="left_back_wheel" />
        <child link="left_back_wheel1" />
        <origin rpy="0 0 0" xyz="0 0 0" />
    </joint>
    <gazebo reference="left_back_wheel">
        <mu1 value="200.0" />
        <mu2 value="100.0" />
        <kp value="10000000.0" />
        <kd value="1.0" />
        <material>Gazebo/Black</material>
    </gazebo>
    <joint name="left_back_wheel_joint" type="continuous">
        <parent link="chassis" />
        <child link="left_back_wheel" />
        <origin rpy="0 0 0" xyz="-0.058 0.115  0.015" />
        <axis xyz="0 1 0" />
        <limit effort="100" velocity="100" />
        <dynamics damping="0.0" friction="0.0" />
    </joint>
    <transmission name="left_back_wheel_trans">
        <type>transmission_interface/SimpleTransmission</type>
        <actuator name="left_back_wheel_motor">
            <hardwareInterface>hardware_interface/EffortJointInterface</hardwareInterface>
            <mechanicalReduction>1</mechanicalReduction>
        </actuator>
        <joint name="left_back_wheel_joint">
            <hardwareInterface>hardware_interface/VelocityJointInterface</hardwareInterface>
        </joint>
    </transmission>
    <!-- /////////////////////////////////////////////////// -->
    <!-- shoulder pan link -->
    <link name="shoulder_pan_link">
        <visual>
            <origin rpy="0 0 0" xyz="-0.0235 -0.014500000000000002 0.075" />
            <geometry>
                <mesh filename="package://robot_arm/meshes/mid-arm.dae" />
            </geometry>
        </visual>
        <collision>
            <origin rpy="0 0 0" xyz="-0.0235 -0.014500000000000002 0.075" />
            <geometry>
                <mesh filename="package://robot_arm/meshes/mid-arm.dae" />
            </geometry>
        </collision>
        <inertial>
            <mass value="0.05" />
            <inertia ixx="1.0" ixy="0.0" ixz="0.0" iyy="1.0" iyz="0.0" izz="1.0" />
            <origin xyz="0 0 0" rpy="0 0 0" />
        </inertial>
    </link>
    <joint name="shoulder_pan_joint" type="revolute">
        <parent link="chassis" />
        <child link="shoulder_pan_link" />
        <origin rpy="0 0 1.57" xyz="0 0 0.07" />
        <axis xyz="0 0 1" />
        <limit effort="100" lower="-2.00" upper="1.57" velocity="100" />
        <dynamics damping="0.0" friction="0.0" />
    </joint>
    <!--  SERVO shoulder pan link motor-->
    <link name="servo_shoulder_roll">
        <visual>
            <origin rpy="4.71 0 1.57" xyz="-0.015 0.04 0" />
            <geometry>
                <mesh filename="package://robot_arm/meshes/Servo Motor.dae" />
            </geometry>
        </visual>
        <collision>
            <origin rpy="4.71 0 1.57" xyz="-0.015 0.04 0" />
            <geometry>
                <mesh filename="package://robot_arm/meshes/Servo Motor.dae" />
            </geometry>
        </collision>
        <inertial>
            <mass value="0.05" />
            <inertia ixx="1.0" ixy="0.0" ixz="0.0" iyy="1.0" iyz="0.0" izz="1.0" />
            <origin xyz="0 0 0" rpy="0 0 0" />
        </inertial>
    </link>
    <gazebo reference="servo_shoulder_roll">
        <turnGravityOff>false</turnGravityOff>
    </gazebo>
    <joint name="servo_joint1" type="fixed">
        <parent link="shoulder_pan_link" />
        <child link="servo_shoulder_roll" />
        <origin rpy="0 0 0" xyz="-0.004 -0.002 0.080" />
    </joint>
    <!-- //////////////////////////////////////////////////////////////////////////////-->
    <link name="shoulder_roll_link">
        <visual>
            <origin rpy="3.14 0 0" xyz="-0.0275 0.0155 -0.015" />
            <geometry>
                <mesh filename="package://robot_arm/meshes/mid-arm.dae" />
            </geometry>
        </visual>
        <collision>
            <origin rpy="3.14 0 0" xyz="-0.0275 0.0155 -0.015" />
            <geometry>
                <mesh filename="package://robot_arm/meshes/mid-arm.dae" />
            </geometry>
        </collision>
        <inertial>
            <mass value="0.05" />
            <inertia ixx="1.0" ixy="0.0" ixz="0.0" iyy="1.0" iyz="0.0" izz="1.0" />
            <origin xyz="0 0 0" rpy="0 0 0" />
        </inertial>
    </link>
    <joint name="shoulder_roll_joint" type="revolute">
        <parent link="shoulder_pan_link" />
        <child link="shoulder_roll_link" />
        <origin rpy="0 0 0" xyz="0 0 0.06" />
        <axis xyz="1 0 0" />
        <limit effort="100" lower="-1.57" upper="2.00" velocity="100" />
        <dynamics damping="0.0" friction="0.0" />
    </joint>
    <!-- SERVO elbow roll motor-->
    <link name="servo_elbow_pan">
        <visual>
            <origin rpy="3.14 0 3.14" xyz="-0.035 -0.016 0" />
            <geometry>
                <mesh filename="package://robot_arm/meshes/Servo Motor.dae" />
            </geometry>
        </visual>
        <collision>
            <origin rpy="3.14 0 3.14" xyz="-0.035 -0.016 0" />
            <geometry>
                <mesh filename="package://robot_arm/meshes/Servo Motor.dae" />
            </geometry>
        </collision>
        <inertial>
            <mass value="0.05" />
            <inertia ixx="1.0" ixy="0.0" ixz="0.0" iyy="1.0" iyz="0.0" izz="1.0" />
            <origin xyz="0 0 0" rpy="0 0 0" />
        </inertial>
    </link>
    <gazebo reference="servo_elbow_pan">
        <turnGravityOff>false</turnGravityOff>
    </gazebo>
    <joint name="servo_joint2" type="fixed">
        <parent link="shoulder_roll_link" />
        <child link="servo_elbow_pan" />
        <origin rpy="0 0 0" xyz="0 0 0.040" />
    </joint>
    <!--/////////////////////////////////////////////////////////////////////////////////////-->
    <link name="elbow_pan_link">
        <visual>
            <origin rpy="0 0 0" xyz="-0.0235 -0.0125 0.09" />
            <geometry>
                <mesh filename="package://robot_arm/meshes/mid-arm.dae" />
            </geometry>
        </visual>
        <collision>
            <origin rpy="0 0 0" xyz="-0.0235 -0.0125 0.09" />
            <geometry>
                <mesh filename="package://robot_arm/meshes/mid-arm.dae" />
            </geometry>
        </collision>
        <inertial>
            <mass value="0.05" />
            <inertia ixx="1.0" ixy="0.0" ixz="0.0" iyy="1.0" iyz="0.0" izz="1.0" />
            <origin xyz="0 0 0" rpy="0 0 0" />
        </inertial>
    </link>
    <joint name="elbow_pan_joint" type="revolute">
        <parent link="shoulder_roll_link" />
        <child link="elbow_pan_link" />
        <origin rpy="0 0 1.57" xyz="0 0 0.08" />
        <axis xyz="0 0 1" />
        <limit effort="100" lower="-1.57" upper="1.57" velocity="100" />
        <dynamics damping="0.0" friction="0.0" />
    </joint>
    <!--  SERVO wrist roll link motor-->
    <link name="servo_wrist_roll">
        <visual>
            <origin rpy="4.71 0 1.57" xyz="-0.015 0.04 0" />
            <geometry>
                <mesh filename="package://robot_arm/meshes/Servo Motor.dae" />
            </geometry>
        </visual>
        <collision>
            <origin rpy="4.71 0 1.57" xyz="-0.015 0.04 0" />
            <geometry>
                <mesh filename="package://robot_arm/meshes/Servo Motor.dae" />
            </geometry>
        </collision>
        <inertial>
            <mass value="0.05" />
            <inertia ixx="1.0" ixy="0.0" ixz="0.0" iyy="1.0" iyz="0.0" izz="1.0" />
            <origin xyz="0 0 0" rpy="0 0 0" />
        </inertial>
    </link>
    <gazebo reference="servo_wrist_roll">
        <turnGravityOff>false</turnGravityOff>
    </gazebo>
    <joint name="servo_joint3" type="fixed">
        <parent link="elbow_pan_link" />
        <child link="servo_wrist_roll" />
        <origin rpy="0 0 0" xyz="-0.004 0 0.098" />
    </joint>
    <!--////////////////////////////////////////////////////////////////////////////////////-->
    <!-- elbow pitch link -->
    <link name="elbow_pitch_link">
        <visual>
            <origin rpy="3.14 0 0" xyz="-0.0265 0.0155 -0.015" />
            <geometry>
                <mesh filename="package://robot_arm/meshes/mid-arm.dae" />
            </geometry>
        </visual>
        <collision>
            <origin rpy="3.14 0 0" xyz="-0.0265 0.0155 -0.015" />
            <geometry>
                <mesh filename="package://robot_arm/meshes/mid-arm.dae" />
            </geometry>
        </collision>
        <inertial>
            <mass value="0.05" />
            <inertia ixx="1.0" ixy="0.0" ixz="0.0" iyy="1.0" iyz="0.0" izz="1.0" />
            <origin xyz="0 0 0" rpy="0 0 0" />
        </inertial>
    </link>
    <joint name="elbow_pitch_joint" type="revolute">
        <parent link="elbow_pan_link" />
        <child link="elbow_pitch_link" />
        <origin rpy="0 0 0" xyz="0 0 0.078" />
        <axis xyz="1 0 0" />
        <limit effort="100" lower="-1.57" upper="2.00" velocity="100" />
        <dynamics damping="0.0" friction="0.0" />
    </joint>
    <!-- SERVO gripper pan motor-->
    <link name="servo_gripper_pan">
        <visual>
            <origin rpy="3.14 0 3.14" xyz="-0.035 -0.016 0" />
            <geometry>
                <mesh filename="package://robot_arm/meshes/Servo Motor.dae" />
            </geometry>
        </visual>
        <collision>
            <origin rpy="3.14 0 3.14" xyz="-0.035 -0.016 0" />
            <geometry>
                <mesh filename="package://robot_arm/meshes/Servo Motor.dae" />
            </geometry>
        </collision>
        <inertial>
            <mass value="0.05" />
            <inertia ixx="1.0" ixy="0.0" ixz="0.0" iyy="1.0" iyz="0.0" izz="1.0" />
            <origin xyz="0 0 0" rpy="0 0 0" />
        </inertial>
    </link>
    <gazebo reference="servo_gripper_pan">
        <turnGravityOff>false</turnGravityOff>
    </gazebo>
    <joint name="servo_joint4" type="fixed">
        <parent link="elbow_pitch_link" />
        <child link="servo_gripper_pan" />
        <origin rpy="0 0 0" xyz="0 0 0.03" />
    </joint>
    <!-- ////////////////////////////////////////////////////////////////////////////-->
    <link name="gripper_pan_link">
        <visual>
            <origin rpy="0 0 0" xyz="0 0 0" />
            <geometry>
                <cylinder length="0.05" radius="0.005" />
            </geometry>
            <material name="Black" />
        </visual>
        <collision>
            <origin rpy="0 0 0" xyz="0 0 0" />
            <geometry>
                <cylinder length="0.05" radius="0.005" />
            </geometry>
        </collision>
        <inertial>
            <mass value="0.01" />
            <inertia ixx="1.0" ixy="0.0" ixz="0.0" iyy="1.0" iyz="0.0" izz="1.0" />
            <origin xyz="0 0 0" rpy="0 0 0" />
        </inertial>
    </link>
    <gazebo reference="gripper_pan_link">
        <material>Gazebo/Black</material>
    </gazebo>
    <joint name="gripper_pan_joint" type="revolute">
        <parent link="elbow_pitch_link" />
        <child link="gripper_pan_link" />
        <origin rpy="0 0 0" xyz="0 0 0.09" />
        <axis xyz="0 0 1" />
        <limit effort="100" lower="-1.57" upper="1.57" velocity="100" />
        <dynamics damping="0.0" friction="0.0" />
    </joint>
    <link name="gripper_pitch_link">
        <visual>
            <origin rpy="0 0 0" xyz="0 0 0" />
            <geometry>
                <cylinder length="0.05" radius="0.005" />
            </geometry>
            <material name="Black" />
        </visual>
        <collision>
            <origin rpy="0 0 0" xyz="0 0 0" />
            <geometry>
                <cylinder length="0.05" radius="0.005" />
            </geometry>
        </collision>
        <inertial>
            <mass value="0.01" />
            <inertia ixx="1.0" ixy="0.0" ixz="0.0" iyy="1.0" iyz="0.0" izz="1.0" />
            <origin xyz="0 0 0" rpy="0 0 0" />
        </inertial>
    </link>
    <gazebo reference="gripper_pitch_link">
        <material>Gazebo/Black</material>
    </gazebo>
    <joint name="gripper_pitch_joint" type="revolute">
        <parent link="gripper_pan_link" />
        <child link="gripper_pitch_link" />
        <origin rpy="0 1.57 0" xyz="0 0 0.02" />
        <axis xyz="0 1 0" />
        <limit effort="100" lower="-1.57" upper="1.57" velocity="100" />
        <dynamics damping="0.0" friction="0.0" />
    </joint>
    <!--////////////////////////////////////////////////////////////////-->
    <joint name="left_gripper_joint" type="revolute">
        <axis xyz="-1 0 0" />
        <limit effort="100.0" lower="0.15" upper="0.75" velocity="1" />
        <origin rpy="0 -1.57 0" xyz="0 0.01 0" />
        <parent link="gripper_pitch_link" />
        <child link="left_gripper" />
        <safety_controller k_position="20" k_velocity="20" soft_lower_limit="0.0" soft_upper_limit="0.45" />
        <dynamics damping="50" friction="1" />
    </joint>
    <link name="left_gripper">
        <visual>
            <origin rpy="0 -1.57 0.0" xyz="0 0 0" />
            <geometry>
                <mesh filename="package://urdf_tutorial/meshes/l_finger.dae" />
            </geometry>
        </visual>
        <collision>
            <geometry>
                <mesh filename="package://urdf_tutorial/meshes/l_finger.dae" />
            </geometry>
            <origin rpy="0 -1.57 0.0" xyz="0 0 0" />
        </collision>
        <inertial>
            <mass value="0.05" />
            <inertia ixx="1.0" ixy="0.0" ixz="0.0" iyy="1.0" iyz="0.0" izz="1.0" />
            <origin xyz="0 0 0" rpy="0 0 0" />
        </inertial>
    </link>
    <joint name="left_tip_joint" type="fixed">
        <parent link="left_gripper" />
        <child link="left_tip" />
    </joint>
    <link name="left_tip">
        <visual>
            <origin rpy="0 -1.57 0.0" xyz="0 0.00495 0.09137" />
            <geometry>
                <mesh filename="package://urdf_tutorial/meshes/l_finger_tip.dae" />
            </geometry>
        </visual>
        <collision>
            <geometry>
                <mesh filename="package://urdf_tutorial/meshes/l_finger_tip.dae" />
            </geometry>
            <origin rpy="0 -1.57 0.0" xyz="0 0.00495 0.09137" />
        </collision>
        <inertial>
            <mass value="0.05" />
            <inertia ixx="1.0" ixy="0.0" ixz="0.0" iyy="1.0" iyz="0.0" izz="1.0" />
            <origin xyz="0 0 0" rpy="0 0 0" />
        </inertial>
    </link>
    <joint name="right_gripper_joint" type="revolute">
        <axis xyz="1 0 0" />
        <limit effort="100.0" lower="0.15" upper="0.75" velocity="1" />
        <origin rpy="0 -1.57 0" xyz="0 -0.01 0" />
        <parent link="gripper_pitch_link" />
        <child link="right_gripper" />
        <safety_controller k_position="20" k_velocity="20" soft_lower_limit="0.0" soft_upper_limit="0.45" />
        <dynamics damping="50" friction="1" />
    </joint>
    <link name="right_gripper">
        <visual>
            <origin rpy="0 -1.57 -3.14" xyz="0 0 0" />
            <geometry>
                <mesh filename="package://urdf_tutorial/meshes/l_finger.dae" />
            </geometry>
        </visual>
        <collision>
            <geometry>
                <mesh filename="package://urdf_tutorial/meshes/l_finger.dae" />
            </geometry>
            <origin rpy="0 -1.57 -3.14" xyz="0 0 0" />
        </collision>
        <inertial>
            <mass value="0.05" />
            <inertia ixx="1.0" ixy="0.0" ixz="0.0" iyy="1.0" iyz="0.0" izz="1.0" />
            <origin xyz="0 0 0" rpy="0 0 0" />
        </inertial>
    </link>
    <joint name="right_tip_joint" type="fixed">
        <parent link="right_gripper" />
        <child link="right_tip" />
    </joint>
    <link name="right_tip">
        <visual>
            <origin rpy="0 -1.57 -3.14" xyz="0 -0.00495 0.09137" />
            <geometry>
                <mesh filename="package://urdf_tutorial/meshes/l_finger_tip.dae" />
            </geometry>
        </visual>
        <collision>
            <geometry>
                <mesh filename="package://urdf_tutorial/meshes/l_finger_tip.dae" />
            </geometry>
            <origin rpy="0 -1.57 -3.14" xyz="0 -0.00495 0.09137" />
        </collision>
        <inertial>
            <mass value="0.05" />
            <inertia ixx="1.0" ixy="0.0" ixz="0.0" iyy="1.0" iyz="0.0" izz="1.0" />
            <origin xyz="0 0 0" rpy="0 0 0" />
        </inertial>
    </link>
    <!-- Grasping frame -->
    <link name="grasping_frame">
        <inertial>
            <origin rpy="0 0 0" xyz="0 0 0" />
            <mass value="0.0001" />
            <cuboid_inertia mass="0.0001" x="0.001" y="0.001" z="0.001" />
            <inertia ixx="1.0" ixy="0.0" ixz="0.0" iyy="100.0" iyz="0.0" izz="1.0" />
        </inertial>
        <visual>
            <origin xyz="0 0 0" />
            <geometry>
                <box size="0.0 0.0 0.0" />
            </geometry>
            <material name="White" />
        </visual>
    </link>
    <joint name="grasping_frame_joint" type="fixed">
        <parent link="gripper_pitch_link" />
        s
        <child link="grasping_frame" />
        <origin rpy="0 0 0" xyz="-0.1 0 0" />
    </joint>
    <!-- //////////////////////////////////////////////////////////////// -->
    <!-- ///////////////////      2D-LiDAR      ///////////////////////   -->
    <!-- LiDAR Link -->
    <link name="lidar_link">
        <visual>
            <geometry>
                <cylinder length="0.04" radius="0.025" />
            </geometry>
            <material name="Gray" />
        </visual>
        <collision>
            <geometry>
                <cylinder length="0.04" radius="0.025" />
            </geometry>
        </collision>
        <inertial>
            <mass value="0.02" />
            <origin xyz="0 0 0" rpy="0 0 0" />
            <inertia ixx="0.0001" ixy="0" ixz="0" iyy="0.0001" iyz="0" izz="0.0001" />
        </inertial>
    </link>
    <!-- LIDAR Joint -->
    <joint name="lidar_joint" type="fixed">
        <parent link="chassis" />
        <child link="lidar_link" />
        <origin rpy="0 0 0" xyz="0.065 0 0.067" />
    </joint>
    <!-- //////////////////////////////////////////////////////////////// -->
    <!-- //////////////////      Stereo RS Camera     //////////////////   -->
    <!-- Stereo Camera Link -->
    <link name="stereo_camera_link">
        <visual>
            <geometry>
                <box size="0.01 0.08 0.01" />
            </geometry>
            <material name="Gray" />
        </visual>
        <collision>
            <geometry>
                <box size="0.01 0.08 0.01" />
            </geometry>
        </collision>
        <inertial>
            <mass value="0.02" />
            <inertia ixx="0.001" ixy="0" ixz="0" iyy="0.001" iyz="0" izz="0.001" />
            <origin xyz="0 0 0" rpy="0 0 0" />
        </inertial>
    </link>
    <!-- Stereo Camera Joints -->
    <joint name="stereo_camera_joint" type="fixed">
        <parent link="chassis" />
        <child link="stereo_camera_link" />
        <origin rpy="0 0 0" xyz="0.095 0 0.039" />
    </joint>
    <!-- //////////////////////////////////////////////////////////////// -->
    <!-- Transmission for ROS CONTROL-->
    <transmission name="shoulder_pan_joint_trans">
        <type>transmission_interface/SimpleTransmission</type>
        <joint name="shoulder_pan_joint">
            <hardwareInterface>hardware_interface/PositionJointInterface</hardwareInterface>
        </joint>
        <actuator name="shoulder_pan_joint_motor">
            <hardwareInterface>hardware_interface/PositionJointInterface</hardwareInterface>
            <mechanicalReduction>1</mechanicalReduction>
        </actuator>
    </transmission>
    <transmission name="shoulder_roll_joint_trans">
        <type>transmission_interface/SimpleTransmission</type>
        <joint name="shoulder_roll_joint">
            <hardwareInterface>hardware_interface/PositionJointInterface</hardwareInterface>
        </joint>
        <actuator name="shoulder_roll_joint_motor">
            <hardwareInterface>hardware_interface/PositionJointInterface</hardwareInterface>
            <mechanicalReduction>1</mechanicalReduction>
        </actuator>
    </transmission>
    <transmission name="elbow_pan_joint_trans">
        <type>transmission_interface/SimpleTransmission</type>
        <joint name="elbow_pan_joint">
            <hardwareInterface>hardware_interface/PositionJointInterface</hardwareInterface>
        </joint>
        <actuator name="elbow_pan_joint_motor">
            <hardwareInterface>hardware_interface/PositionJointInterface</hardwareInterface>
            <mechanicalReduction>1</mechanicalReduction>
        </actuator>
    </transmission>
    <transmission name="elbow_pitch_joint_trans">
        <type>transmission_interface/SimpleTransmission</type>
        <joint name="elbow_pitch_joint">
            <hardwareInterface>hardware_interface/PositionJointInterface</hardwareInterface>
        </joint>
        <actuator name="elbow_pitch_joint_motor">
            <hardwareInterface>hardware_interface/PositionJointInterface</hardwareInterface>
            <mechanicalReduction>1</mechanicalReduction>
        </actuator>
    </transmission>
    <transmission name="gripper_pan_joint_trans">
        <type>transmission_interface/SimpleTransmission</type>
        <joint name="gripper_pan_joint">
            <hardwareInterface>hardware_interface/PositionJointInterface</hardwareInterface>
        </joint>
        <actuator name="gripper_pan_joint_motor">
            <hardwareInterface>hardware_interface/PositionJointInterface</hardwareInterface>
            <mechanicalReduction>1</mechanicalReduction>
        </actuator>
    </transmission>
    <transmission name="left_gripper_joint_trans">
        <type>transmission_interface/SimpleTransmission</type>
        <joint name="left_gripper_joint">
            <hardwareInterface>hardware_interface/PositionJointInterface</hardwareInterface>
        </joint>
        <actuator name="left_gripper_joint_motor">
            <hardwareInterface>hardware_interface/PositionJointInterface</hardwareInterface>
            <mechanicalReduction>1</mechanicalReduction>
        </actuator>
    </transmission>
    <transmission name="right_gripper_joint_trans">
        <type>transmission_interface/SimpleTransmission</type>
        <joint name="right_gripper_joint">
            <hardwareInterface>hardware_interface/PositionJointInterface</hardwareInterface>
        </joint>
        <actuator name="right_gripper_joint_motor">
            <hardwareInterface>hardware_interface/PositionJointInterface</hardwareInterface>
            <mechanicalReduction>1</mechanicalReduction>
        </actuator>
    </transmission>
    <transmission name="gripper_pitch_joint_trans">
        <type>transmission_interface/SimpleTransmission</type>
        <joint name="gripper_pitch_joint">
            <hardwareInterface>hardware_interface/PositionJointInterface</hardwareInterface>
        </joint>
        <actuator name="gripper_pitch_joint_motor">
            <hardwareInterface>hardware_interface/PositionJointInterface</hardwareInterface>
            <mechanicalReduction>1</mechanicalReduction>
        </actuator>
    </transmission>
    <!-- ros_control plugin-->
    <gazebo>
        <plugin filename="libgazebo_ros_control.so" name="gazebo_ros_control">
            <robotNamespace>/</robotNamespace>
        </plugin>
    </gazebo>
    <!-- lidar sensor -->
    <gazebo reference="lidar_link">
        <sensor name="lidar" type="ray">
            <pose>0 0 0 0 0 0</pose>
            <visualize>true</visualize>
            <update_rate>20</update_rate>
            <ray>
                <scan>
                    <horizontal>
                        <samples>600</samples>
                        <resolution>0.5</resolution>
                        <min_angle>-1.4</min_angle>
                        <max_angle>1.4</max_angle>
                    </horizontal>
                </scan>
                <range>
                    <min>0.05</min>
                    <max>8</max>
                    <resolution>0.01</resolution>
                </range>
            </ray>
            <plugin filename="libgazebo_ros_laser.so" name="gazebo_ros_laser">
                <topicName>/scan</topicName>
                <frameName>lidar_link</frameName>
            </plugin>
        </sensor>
    </gazebo>
    <!-- Left Camera Sensor -->
    <gazebo reference="stereo_camera_link">
        <sensor name="stereo_camera_left_sensor" type="camera">
            <pose>0 0.03 0 0 0 0</pose>
            <!-- Positioned to the left -->
            <camera>
                <horizontal_fov>1.047</horizontal_fov>
                <image>
                    <width>640</width>
                    <height>480</height>
                    <format>R8G8B8</format>
                </image>
                <clip>
                    <near>0.01</near>
                    <far>50</far>
                </clip>
            </camera>
            <plugin filename="libgazebo_ros_camera.so" name="stereo_camera_left_plugin">
                <robotNamespace>/</robotNamespace>
                <cameraName>stereo_camera_left</cameraName>
            </plugin>
        </sensor>
        <!-- Right Camera Sensor -->
        <sensor name="stereo_camera_right_sensor" type="camera">
            <pose>0 -0.03 0 0 0 0</pose>
            <!-- Positioned to the right -->
            <camera>
                <horizontal_fov>1.047</horizontal_fov>
                <image>
                    <width>640</width>
                    <height>480</height>
                    <format>R8G8B8</format>
                </image>
                <clip>
                    <near>0.01</near>
                    <far>50</far>
                </clip>
            </camera>
            <plugin filename="libgazebo_ros_camera.so" name="stereo_camera_right_plugin">
                <robotNamespace>/</robotNamespace>
                <cameraName>stereo_camera_right</cameraName>
            </plugin>
        </sensor>
    </gazebo>
</robot>

